2023-05-02 16:21:55,557 INFO [31m[1mWARNING: This is a development server. Do not use it in a production deployment. Use a production WSGI server instead.[0m
 * Running on http://127.0.0.1:8080
2023-05-02 16:21:55,557 INFO [33mPress CTRL+C to quit[0m
2023-05-02 16:21:57,898 INFO Scheduler started
2023-05-02 16:21:57,898 INFO Application started
2023-05-02 20:17:35,961 INFO [31m[1mWARNING: This is a development server. Do not use it in a production deployment. Use a production WSGI server instead.[0m
 * Running on http://127.0.0.1:8080
2023-05-02 20:17:35,961 INFO [33mPress CTRL+C to quit[0m
2023-05-02 20:17:38,712 INFO Scheduler started
2023-05-02 20:17:38,712 INFO Application started
2023-05-02 21:58:07,692 INFO 127.0.0.1 - - [02/May/2023 21:58:07] "POST /api/116/alice HTTP/1.1" 200 -
2023-05-02 22:00:45,863 INFO 127.0.0.1 - - [02/May/2023 22:00:45] "POST /api/116/alice HTTP/1.1" 200 -
2023-05-02 22:01:43,086 INFO 127.0.0.1 - - [02/May/2023 22:01:43] "[33mGET /api/116/alice HTTP/1.1[0m" 404 -
2023-05-02 23:04:16,477 ERROR Error while getting Updates: httpx.LocalProtocolError: Invalid input ConnectionInputs.RECV_WINDOW_UPDATE in state ConnectionState.CLOSED
2023-05-02 23:04:16,478 ERROR No error handlers are registered, logging exception.
Traceback (most recent call last):
  File "C:\Users\alexs\PythonProjects\AChtoZadano\.venv\Lib\site-packages\h2\connection.py", line 224, in process_input
    func, target_state = self._transitions[(self.state, input_)]
                         ~~~~~~~~~~~~~~~~~^^^^^^^^^^^^^^^^^^^^^^
KeyError: (<ConnectionState.CLOSED: 3>, <ConnectionInputs.RECV_WINDOW_UPDATE: 13>)

During handling of the above exception, another exception occurred:

Traceback (most recent call last):
  File "C:\Users\alexs\PythonProjects\AChtoZadano\.venv\Lib\site-packages\httpcore\_async\http2.py", line 112, in handle_async_request
    status, headers = await self._receive_response(
                      ^^^^^^^^^^^^^^^^^^^^^^^^^^^^^
  File "C:\Users\alexs\PythonProjects\AChtoZadano\.venv\Lib\site-packages\httpcore\_async\http2.py", line 229, in _receive_response
    event = await self._receive_stream_event(request, stream_id)
            ^^^^^^^^^^^^^^^^^^^^^^^^^^^^^^^^^^^^^^^^^^^^^^^^^^^^
  File "C:\Users\alexs\PythonProjects\AChtoZadano\.venv\Lib\site-packages\httpcore\_async\http2.py", line 260, in _receive_stream_event
    await self._receive_events(request, stream_id)
  File "C:\Users\alexs\PythonProjects\AChtoZadano\.venv\Lib\site-packages\httpcore\_async\http2.py", line 281, in _receive_events
    events = await self._read_incoming_data(request)
             ^^^^^^^^^^^^^^^^^^^^^^^^^^^^^^^^^^^^^^^
  File "C:\Users\alexs\PythonProjects\AChtoZadano\.venv\Lib\site-packages\httpcore\_async\http2.py", line 343, in _read_incoming_data
    events: typing.List[h2.events.Event] = self._h2_state.receive_data(data)
                                           ^^^^^^^^^^^^^^^^^^^^^^^^^^^^^^^^^
  File "C:\Users\alexs\PythonProjects\AChtoZadano\.venv\Lib\site-packages\h2\connection.py", line 1463, in receive_data
    events.extend(self._receive_frame(frame))
                  ^^^^^^^^^^^^^^^^^^^^^^^^^^
  File "C:\Users\alexs\PythonProjects\AChtoZadano\.venv\Lib\site-packages\h2\connection.py", line 1487, in _receive_frame
    frames, events = self._frame_dispatch_table[frame.__class__](frame)
                     ^^^^^^^^^^^^^^^^^^^^^^^^^^^^^^^^^^^^^^^^^^^^^^^^^^
  File "C:\Users\alexs\PythonProjects\AChtoZadano\.venv\Lib\site-packages\h2\connection.py", line 1728, in _receive_window_update_frame
    events = self.state_machine.process_input(
             ^^^^^^^^^^^^^^^^^^^^^^^^^^^^^^^^^
  File "C:\Users\alexs\PythonProjects\AChtoZadano\.venv\Lib\site-packages\h2\connection.py", line 228, in process_input
    raise ProtocolError(
h2.exceptions.ProtocolError: Invalid input ConnectionInputs.RECV_WINDOW_UPDATE in state ConnectionState.CLOSED

During handling of the above exception, another exception occurred:

Traceback (most recent call last):
  File "C:\Users\alexs\PythonProjects\AChtoZadano\.venv\Lib\site-packages\httpx\_transports\default.py", line 60, in map_httpcore_exceptions
    yield
  File "C:\Users\alexs\PythonProjects\AChtoZadano\.venv\Lib\site-packages\httpx\_transports\default.py", line 353, in handle_async_request
    resp = await self._pool.handle_async_request(req)
           ^^^^^^^^^^^^^^^^^^^^^^^^^^^^^^^^^^^^^^^^^^
  File "C:\Users\alexs\PythonProjects\AChtoZadano\.venv\Lib\site-packages\httpcore\_async\connection_pool.py", line 253, in handle_async_request
    raise exc
  File "C:\Users\alexs\PythonProjects\AChtoZadano\.venv\Lib\site-packages\httpcore\_async\connection_pool.py", line 237, in handle_async_request
    response = await connection.handle_async_request(request)
               ^^^^^^^^^^^^^^^^^^^^^^^^^^^^^^^^^^^^^^^^^^^^^^
  File "C:\Users\alexs\PythonProjects\AChtoZadano\.venv\Lib\site-packages\httpcore\_async\connection.py", line 90, in handle_async_request
    return await self._connection.handle_async_request(request)
           ^^^^^^^^^^^^^^^^^^^^^^^^^^^^^^^^^^^^^^^^^^^^^^^^^^^^
  File "C:\Users\alexs\PythonProjects\AChtoZadano\.venv\Lib\site-packages\httpcore\_async\http2.py", line 142, in handle_async_request
    raise LocalProtocolError(exc)  # pragma: nocover
    ^^^^^^^^^^^^^^^^^^^^^^^^^^^^^
httpcore.LocalProtocolError: Invalid input ConnectionInputs.RECV_WINDOW_UPDATE in state ConnectionState.CLOSED

The above exception was the direct cause of the following exception:

Traceback (most recent call last):
  File "C:\Users\alexs\PythonProjects\AChtoZadano\.venv\Lib\site-packages\telegram\request\_httpxrequest.py", line 199, in do_request
    res = await self._client.request(
          ^^^^^^^^^^^^^^^^^^^^^^^^^^^
  File "C:\Users\alexs\PythonProjects\AChtoZadano\.venv\Lib\site-packages\httpx\_client.py", line 1533, in request
    return await self.send(request, auth=auth, follow_redirects=follow_redirects)
           ^^^^^^^^^^^^^^^^^^^^^^^^^^^^^^^^^^^^^^^^^^^^^^^^^^^^^^^^^^^^^^^^^^^^^^
  File "C:\Users\alexs\PythonProjects\AChtoZadano\.venv\Lib\site-packages\httpx\_client.py", line 1620, in send
    response = await self._send_handling_auth(
               ^^^^^^^^^^^^^^^^^^^^^^^^^^^^^^^
  File "C:\Users\alexs\PythonProjects\AChtoZadano\.venv\Lib\site-packages\httpx\_client.py", line 1648, in _send_handling_auth
    response = await self._send_handling_redirects(
               ^^^^^^^^^^^^^^^^^^^^^^^^^^^^^^^^^^^^
  File "C:\Users\alexs\PythonProjects\AChtoZadano\.venv\Lib\site-packages\httpx\_client.py", line 1685, in _send_handling_redirects
    response = await self._send_single_request(request)
               ^^^^^^^^^^^^^^^^^^^^^^^^^^^^^^^^^^^^^^^^
  File "C:\Users\alexs\PythonProjects\AChtoZadano\.venv\Lib\site-packages\httpx\_client.py", line 1722, in _send_single_request
    response = await transport.handle_async_request(request)
               ^^^^^^^^^^^^^^^^^^^^^^^^^^^^^^^^^^^^^^^^^^^^^
  File "C:\Users\alexs\PythonProjects\AChtoZadano\.venv\Lib\site-packages\httpx\_transports\default.py", line 352, in handle_async_request
    with map_httpcore_exceptions():
  File "C:\Program Files\Python311\Lib\contextlib.py", line 155, in __exit__
    self.gen.throw(typ, value, traceback)
  File "C:\Users\alexs\PythonProjects\AChtoZadano\.venv\Lib\site-packages\httpx\_transports\default.py", line 77, in map_httpcore_exceptions
    raise mapped_exc(message) from exc
httpx.LocalProtocolError: Invalid input ConnectionInputs.RECV_WINDOW_UPDATE in state ConnectionState.CLOSED

The above exception was the direct cause of the following exception:

Traceback (most recent call last):
  File "C:\Users\alexs\PythonProjects\AChtoZadano\.venv\Lib\site-packages\telegram\ext\_updater.py", line 607, in _network_loop_retry
    if not await action_cb():
           ^^^^^^^^^^^^^^^^^
  File "C:\Users\alexs\PythonProjects\AChtoZadano\.venv\Lib\site-packages\telegram\ext\_updater.py", line 335, in polling_action_cb
    raise exc
  File "C:\Users\alexs\PythonProjects\AChtoZadano\.venv\Lib\site-packages\telegram\ext\_updater.py", line 320, in polling_action_cb
    updates = await self.bot.get_updates(
              ^^^^^^^^^^^^^^^^^^^^^^^^^^^
  File "C:\Users\alexs\PythonProjects\AChtoZadano\.venv\Lib\site-packages\telegram\ext\_extbot.py", line 524, in get_updates
    updates = await super().get_updates(
              ^^^^^^^^^^^^^^^^^^^^^^^^^^
  File "C:\Users\alexs\PythonProjects\AChtoZadano\.venv\Lib\site-packages\telegram\_bot.py", line 331, in decorator
    result = await func(*args, **kwargs)  # skipcq: PYL-E1102
             ^^^^^^^^^^^^^^^^^^^^^^^^^^^
  File "C:\Users\alexs\PythonProjects\AChtoZadano\.venv\Lib\site-packages\telegram\_bot.py", line 3510, in get_updates
    await self._post(
  File "C:\Users\alexs\PythonProjects\AChtoZadano\.venv\Lib\site-packages\telegram\_bot.py", line 419, in _post
    return await self._do_post(
           ^^^^^^^^^^^^^^^^^^^^
  File "C:\Users\alexs\PythonProjects\AChtoZadano\.venv\Lib\site-packages\telegram\ext\_extbot.py", line 306, in _do_post
    return await super()._do_post(
           ^^^^^^^^^^^^^^^^^^^^^^^
  File "C:\Users\alexs\PythonProjects\AChtoZadano\.venv\Lib\site-packages\telegram\_bot.py", line 450, in _do_post
    return await request.post(
           ^^^^^^^^^^^^^^^^^^^
  File "C:\Users\alexs\PythonProjects\AChtoZadano\.venv\Lib\site-packages\telegram\request\_baserequest.py", line 165, in post
    result = await self._request_wrapper(
             ^^^^^^^^^^^^^^^^^^^^^^^^^^^^
  File "C:\Users\alexs\PythonProjects\AChtoZadano\.venv\Lib\site-packages\telegram\request\_baserequest.py", line 288, in _request_wrapper
    raise exc
  File "C:\Users\alexs\PythonProjects\AChtoZadano\.venv\Lib\site-packages\telegram\request\_baserequest.py", line 274, in _request_wrapper
    code, payload = await self.do_request(
                    ^^^^^^^^^^^^^^^^^^^^^^
  File "C:\Users\alexs\PythonProjects\AChtoZadano\.venv\Lib\site-packages\telegram\request\_httpxrequest.py", line 223, in do_request
    raise NetworkError(f"httpx.{err.__class__.__name__}: {err}") from err
telegram.error.NetworkError: httpx.LocalProtocolError: Invalid input ConnectionInputs.RECV_WINDOW_UPDATE in state ConnectionState.CLOSED
2023-05-02 23:04:17,488 ERROR Error while getting Updates: httpx.LocalProtocolError: Invalid input ConnectionInputs.SEND_HEADERS in state ConnectionState.CLOSED
2023-05-02 23:04:17,489 ERROR No error handlers are registered, logging exception.
Traceback (most recent call last):
  File "C:\Users\alexs\PythonProjects\AChtoZadano\.venv\Lib\site-packages\h2\connection.py", line 224, in process_input
    func, target_state = self._transitions[(self.state, input_)]
                         ~~~~~~~~~~~~~~~~~^^^^^^^^^^^^^^^^^^^^^^
KeyError: (<ConnectionState.CLOSED: 3>, <ConnectionInputs.SEND_HEADERS: 0>)

During handling of the above exception, another exception occurred:

Traceback (most recent call last):
  File "C:\Users\alexs\PythonProjects\AChtoZadano\.venv\Lib\site-packages\httpcore\_async\http2.py", line 106, in handle_async_request
    await self._send_request_headers(request=request, stream_id=stream_id)
  File "C:\Users\alexs\PythonProjects\AChtoZadano\.venv\Lib\site-packages\httpcore\_async\http2.py", line 203, in _send_request_headers
    self._h2_state.send_headers(stream_id, headers, end_stream=end_stream)
  File "C:\Users\alexs\PythonProjects\AChtoZadano\.venv\Lib\site-packages\h2\connection.py", line 766, in send_headers
    self.state_machine.process_input(ConnectionInputs.SEND_HEADERS)
  File "C:\Users\alexs\PythonProjects\AChtoZadano\.venv\Lib\site-packages\h2\connection.py", line 228, in process_input
    raise ProtocolError(
h2.exceptions.ProtocolError: Invalid input ConnectionInputs.SEND_HEADERS in state ConnectionState.CLOSED

During handling of the above exception, another exception occurred:

Traceback (most recent call last):
  File "C:\Users\alexs\PythonProjects\AChtoZadano\.venv\Lib\site-packages\httpx\_transports\default.py", line 60, in map_httpcore_exceptions
    yield
  File "C:\Users\alexs\PythonProjects\AChtoZadano\.venv\Lib\site-packages\httpx\_transports\default.py", line 353, in handle_async_request
    resp = await self._pool.handle_async_request(req)
           ^^^^^^^^^^^^^^^^^^^^^^^^^^^^^^^^^^^^^^^^^^
  File "C:\Users\alexs\PythonProjects\AChtoZadano\.venv\Lib\site-packages\httpcore\_async\connection_pool.py", line 253, in handle_async_request
    raise exc
  File "C:\Users\alexs\PythonProjects\AChtoZadano\.venv\Lib\site-packages\httpcore\_async\connection_pool.py", line 237, in handle_async_request
    response = await connection.handle_async_request(request)
               ^^^^^^^^^^^^^^^^^^^^^^^^^^^^^^^^^^^^^^^^^^^^^^
  File "C:\Users\alexs\PythonProjects\AChtoZadano\.venv\Lib\site-packages\httpcore\_async\connection.py", line 90, in handle_async_request
    return await self._connection.handle_async_request(request)
           ^^^^^^^^^^^^^^^^^^^^^^^^^^^^^^^^^^^^^^^^^^^^^^^^^^^^
  File "C:\Users\alexs\PythonProjects\AChtoZadano\.venv\Lib\site-packages\httpcore\_async\http2.py", line 142, in handle_async_request
    raise LocalProtocolError(exc)  # pragma: nocover
    ^^^^^^^^^^^^^^^^^^^^^^^^^^^^^
httpcore.LocalProtocolError: Invalid input ConnectionInputs.SEND_HEADERS in state ConnectionState.CLOSED

The above exception was the direct cause of the following exception:

Traceback (most recent call last):
  File "C:\Users\alexs\PythonProjects\AChtoZadano\.venv\Lib\site-packages\telegram\request\_httpxrequest.py", line 199, in do_request
    res = await self._client.request(
          ^^^^^^^^^^^^^^^^^^^^^^^^^^^
  File "C:\Users\alexs\PythonProjects\AChtoZadano\.venv\Lib\site-packages\httpx\_client.py", line 1533, in request
    return await self.send(request, auth=auth, follow_redirects=follow_redirects)
           ^^^^^^^^^^^^^^^^^^^^^^^^^^^^^^^^^^^^^^^^^^^^^^^^^^^^^^^^^^^^^^^^^^^^^^
  File "C:\Users\alexs\PythonProjects\AChtoZadano\.venv\Lib\site-packages\httpx\_client.py", line 1620, in send
    response = await self._send_handling_auth(
               ^^^^^^^^^^^^^^^^^^^^^^^^^^^^^^^
  File "C:\Users\alexs\PythonProjects\AChtoZadano\.venv\Lib\site-packages\httpx\_client.py", line 1648, in _send_handling_auth
    response = await self._send_handling_redirects(
               ^^^^^^^^^^^^^^^^^^^^^^^^^^^^^^^^^^^^
  File "C:\Users\alexs\PythonProjects\AChtoZadano\.venv\Lib\site-packages\httpx\_client.py", line 1685, in _send_handling_redirects
    response = await self._send_single_request(request)
               ^^^^^^^^^^^^^^^^^^^^^^^^^^^^^^^^^^^^^^^^
  File "C:\Users\alexs\PythonProjects\AChtoZadano\.venv\Lib\site-packages\httpx\_client.py", line 1722, in _send_single_request
    response = await transport.handle_async_request(request)
               ^^^^^^^^^^^^^^^^^^^^^^^^^^^^^^^^^^^^^^^^^^^^^
  File "C:\Users\alexs\PythonProjects\AChtoZadano\.venv\Lib\site-packages\httpx\_transports\default.py", line 352, in handle_async_request
    with map_httpcore_exceptions():
  File "C:\Program Files\Python311\Lib\contextlib.py", line 155, in __exit__
    self.gen.throw(typ, value, traceback)
  File "C:\Users\alexs\PythonProjects\AChtoZadano\.venv\Lib\site-packages\httpx\_transports\default.py", line 77, in map_httpcore_exceptions
    raise mapped_exc(message) from exc
httpx.LocalProtocolError: Invalid input ConnectionInputs.SEND_HEADERS in state ConnectionState.CLOSED

The above exception was the direct cause of the following exception:

Traceback (most recent call last):
  File "C:\Users\alexs\PythonProjects\AChtoZadano\.venv\Lib\site-packages\telegram\ext\_updater.py", line 607, in _network_loop_retry
    if not await action_cb():
           ^^^^^^^^^^^^^^^^^
  File "C:\Users\alexs\PythonProjects\AChtoZadano\.venv\Lib\site-packages\telegram\ext\_updater.py", line 335, in polling_action_cb
    raise exc
  File "C:\Users\alexs\PythonProjects\AChtoZadano\.venv\Lib\site-packages\telegram\ext\_updater.py", line 320, in polling_action_cb
    updates = await self.bot.get_updates(
              ^^^^^^^^^^^^^^^^^^^^^^^^^^^
  File "C:\Users\alexs\PythonProjects\AChtoZadano\.venv\Lib\site-packages\telegram\ext\_extbot.py", line 524, in get_updates
    updates = await super().get_updates(
              ^^^^^^^^^^^^^^^^^^^^^^^^^^
  File "C:\Users\alexs\PythonProjects\AChtoZadano\.venv\Lib\site-packages\telegram\_bot.py", line 331, in decorator
    result = await func(*args, **kwargs)  # skipcq: PYL-E1102
             ^^^^^^^^^^^^^^^^^^^^^^^^^^^
  File "C:\Users\alexs\PythonProjects\AChtoZadano\.venv\Lib\site-packages\telegram\_bot.py", line 3510, in get_updates
    await self._post(
  File "C:\Users\alexs\PythonProjects\AChtoZadano\.venv\Lib\site-packages\telegram\_bot.py", line 419, in _post
    return await self._do_post(
           ^^^^^^^^^^^^^^^^^^^^
  File "C:\Users\alexs\PythonProjects\AChtoZadano\.venv\Lib\site-packages\telegram\ext\_extbot.py", line 306, in _do_post
    return await super()._do_post(
           ^^^^^^^^^^^^^^^^^^^^^^^
  File "C:\Users\alexs\PythonProjects\AChtoZadano\.venv\Lib\site-packages\telegram\_bot.py", line 450, in _do_post
    return await request.post(
           ^^^^^^^^^^^^^^^^^^^
  File "C:\Users\alexs\PythonProjects\AChtoZadano\.venv\Lib\site-packages\telegram\request\_baserequest.py", line 165, in post
    result = await self._request_wrapper(
             ^^^^^^^^^^^^^^^^^^^^^^^^^^^^
  File "C:\Users\alexs\PythonProjects\AChtoZadano\.venv\Lib\site-packages\telegram\request\_baserequest.py", line 288, in _request_wrapper
    raise exc
  File "C:\Users\alexs\PythonProjects\AChtoZadano\.venv\Lib\site-packages\telegram\request\_baserequest.py", line 274, in _request_wrapper
    code, payload = await self.do_request(
                    ^^^^^^^^^^^^^^^^^^^^^^
  File "C:\Users\alexs\PythonProjects\AChtoZadano\.venv\Lib\site-packages\telegram\request\_httpxrequest.py", line 223, in do_request
    raise NetworkError(f"httpx.{err.__class__.__name__}: {err}") from err
telegram.error.NetworkError: httpx.LocalProtocolError: Invalid input ConnectionInputs.SEND_HEADERS in state ConnectionState.CLOSED
2023-05-02 23:04:19,002 ERROR Error while getting Updates: httpx.LocalProtocolError: Invalid input ConnectionInputs.SEND_HEADERS in state ConnectionState.CLOSED
2023-05-02 23:04:19,002 ERROR No error handlers are registered, logging exception.
Traceback (most recent call last):
  File "C:\Users\alexs\PythonProjects\AChtoZadano\.venv\Lib\site-packages\h2\connection.py", line 224, in process_input
    func, target_state = self._transitions[(self.state, input_)]
                         ~~~~~~~~~~~~~~~~~^^^^^^^^^^^^^^^^^^^^^^
KeyError: (<ConnectionState.CLOSED: 3>, <ConnectionInputs.SEND_HEADERS: 0>)

During handling of the above exception, another exception occurred:

Traceback (most recent call last):
  File "C:\Users\alexs\PythonProjects\AChtoZadano\.venv\Lib\site-packages\httpcore\_async\http2.py", line 106, in handle_async_request
    await self._send_request_headers(request=request, stream_id=stream_id)
  File "C:\Users\alexs\PythonProjects\AChtoZadano\.venv\Lib\site-packages\httpcore\_async\http2.py", line 203, in _send_request_headers
    self._h2_state.send_headers(stream_id, headers, end_stream=end_stream)
  File "C:\Users\alexs\PythonProjects\AChtoZadano\.venv\Lib\site-packages\h2\connection.py", line 766, in send_headers
    self.state_machine.process_input(ConnectionInputs.SEND_HEADERS)
  File "C:\Users\alexs\PythonProjects\AChtoZadano\.venv\Lib\site-packages\h2\connection.py", line 228, in process_input
    raise ProtocolError(
h2.exceptions.ProtocolError: Invalid input ConnectionInputs.SEND_HEADERS in state ConnectionState.CLOSED

During handling of the above exception, another exception occurred:

Traceback (most recent call last):
  File "C:\Users\alexs\PythonProjects\AChtoZadano\.venv\Lib\site-packages\httpx\_transports\default.py", line 60, in map_httpcore_exceptions
    yield
  File "C:\Users\alexs\PythonProjects\AChtoZadano\.venv\Lib\site-packages\httpx\_transports\default.py", line 353, in handle_async_request
    resp = await self._pool.handle_async_request(req)
           ^^^^^^^^^^^^^^^^^^^^^^^^^^^^^^^^^^^^^^^^^^
  File "C:\Users\alexs\PythonProjects\AChtoZadano\.venv\Lib\site-packages\httpcore\_async\connection_pool.py", line 253, in handle_async_request
    raise exc
  File "C:\Users\alexs\PythonProjects\AChtoZadano\.venv\Lib\site-packages\httpcore\_async\connection_pool.py", line 237, in handle_async_request
    response = await connection.handle_async_request(request)
               ^^^^^^^^^^^^^^^^^^^^^^^^^^^^^^^^^^^^^^^^^^^^^^
  File "C:\Users\alexs\PythonProjects\AChtoZadano\.venv\Lib\site-packages\httpcore\_async\connection.py", line 90, in handle_async_request
    return await self._connection.handle_async_request(request)
           ^^^^^^^^^^^^^^^^^^^^^^^^^^^^^^^^^^^^^^^^^^^^^^^^^^^^
  File "C:\Users\alexs\PythonProjects\AChtoZadano\.venv\Lib\site-packages\httpcore\_async\http2.py", line 142, in handle_async_request
    raise LocalProtocolError(exc)  # pragma: nocover
    ^^^^^^^^^^^^^^^^^^^^^^^^^^^^^
httpcore.LocalProtocolError: Invalid input ConnectionInputs.SEND_HEADERS in state ConnectionState.CLOSED

The above exception was the direct cause of the following exception:

Traceback (most recent call last):
  File "C:\Users\alexs\PythonProjects\AChtoZadano\.venv\Lib\site-packages\telegram\request\_httpxrequest.py", line 199, in do_request
    res = await self._client.request(
          ^^^^^^^^^^^^^^^^^^^^^^^^^^^
  File "C:\Users\alexs\PythonProjects\AChtoZadano\.venv\Lib\site-packages\httpx\_client.py", line 1533, in request
    return await self.send(request, auth=auth, follow_redirects=follow_redirects)
           ^^^^^^^^^^^^^^^^^^^^^^^^^^^^^^^^^^^^^^^^^^^^^^^^^^^^^^^^^^^^^^^^^^^^^^
  File "C:\Users\alexs\PythonProjects\AChtoZadano\.venv\Lib\site-packages\httpx\_client.py", line 1620, in send
    response = await self._send_handling_auth(
               ^^^^^^^^^^^^^^^^^^^^^^^^^^^^^^^
  File "C:\Users\alexs\PythonProjects\AChtoZadano\.venv\Lib\site-packages\httpx\_client.py", line 1648, in _send_handling_auth
    response = await self._send_handling_redirects(
               ^^^^^^^^^^^^^^^^^^^^^^^^^^^^^^^^^^^^
  File "C:\Users\alexs\PythonProjects\AChtoZadano\.venv\Lib\site-packages\httpx\_client.py", line 1685, in _send_handling_redirects
    response = await self._send_single_request(request)
               ^^^^^^^^^^^^^^^^^^^^^^^^^^^^^^^^^^^^^^^^
  File "C:\Users\alexs\PythonProjects\AChtoZadano\.venv\Lib\site-packages\httpx\_client.py", line 1722, in _send_single_request
    response = await transport.handle_async_request(request)
               ^^^^^^^^^^^^^^^^^^^^^^^^^^^^^^^^^^^^^^^^^^^^^
  File "C:\Users\alexs\PythonProjects\AChtoZadano\.venv\Lib\site-packages\httpx\_transports\default.py", line 352, in handle_async_request
    with map_httpcore_exceptions():
  File "C:\Program Files\Python311\Lib\contextlib.py", line 155, in __exit__
    self.gen.throw(typ, value, traceback)
  File "C:\Users\alexs\PythonProjects\AChtoZadano\.venv\Lib\site-packages\httpx\_transports\default.py", line 77, in map_httpcore_exceptions
    raise mapped_exc(message) from exc
httpx.LocalProtocolError: Invalid input ConnectionInputs.SEND_HEADERS in state ConnectionState.CLOSED

The above exception was the direct cause of the following exception:

Traceback (most recent call last):
  File "C:\Users\alexs\PythonProjects\AChtoZadano\.venv\Lib\site-packages\telegram\ext\_updater.py", line 607, in _network_loop_retry
    if not await action_cb():
           ^^^^^^^^^^^^^^^^^
  File "C:\Users\alexs\PythonProjects\AChtoZadano\.venv\Lib\site-packages\telegram\ext\_updater.py", line 335, in polling_action_cb
    raise exc
  File "C:\Users\alexs\PythonProjects\AChtoZadano\.venv\Lib\site-packages\telegram\ext\_updater.py", line 320, in polling_action_cb
    updates = await self.bot.get_updates(
              ^^^^^^^^^^^^^^^^^^^^^^^^^^^
  File "C:\Users\alexs\PythonProjects\AChtoZadano\.venv\Lib\site-packages\telegram\ext\_extbot.py", line 524, in get_updates
    updates = await super().get_updates(
              ^^^^^^^^^^^^^^^^^^^^^^^^^^
  File "C:\Users\alexs\PythonProjects\AChtoZadano\.venv\Lib\site-packages\telegram\_bot.py", line 331, in decorator
    result = await func(*args, **kwargs)  # skipcq: PYL-E1102
             ^^^^^^^^^^^^^^^^^^^^^^^^^^^
  File "C:\Users\alexs\PythonProjects\AChtoZadano\.venv\Lib\site-packages\telegram\_bot.py", line 3510, in get_updates
    await self._post(
  File "C:\Users\alexs\PythonProjects\AChtoZadano\.venv\Lib\site-packages\telegram\_bot.py", line 419, in _post
    return await self._do_post(
           ^^^^^^^^^^^^^^^^^^^^
  File "C:\Users\alexs\PythonProjects\AChtoZadano\.venv\Lib\site-packages\telegram\ext\_extbot.py", line 306, in _do_post
    return await super()._do_post(
           ^^^^^^^^^^^^^^^^^^^^^^^
  File "C:\Users\alexs\PythonProjects\AChtoZadano\.venv\Lib\site-packages\telegram\_bot.py", line 450, in _do_post
    return await request.post(
           ^^^^^^^^^^^^^^^^^^^
  File "C:\Users\alexs\PythonProjects\AChtoZadano\.venv\Lib\site-packages\telegram\request\_baserequest.py", line 165, in post
    result = await self._request_wrapper(
             ^^^^^^^^^^^^^^^^^^^^^^^^^^^^
  File "C:\Users\alexs\PythonProjects\AChtoZadano\.venv\Lib\site-packages\telegram\request\_baserequest.py", line 288, in _request_wrapper
    raise exc
  File "C:\Users\alexs\PythonProjects\AChtoZadano\.venv\Lib\site-packages\telegram\request\_baserequest.py", line 274, in _request_wrapper
    code, payload = await self.do_request(
                    ^^^^^^^^^^^^^^^^^^^^^^
  File "C:\Users\alexs\PythonProjects\AChtoZadano\.venv\Lib\site-packages\telegram\request\_httpxrequest.py", line 223, in do_request
    raise NetworkError(f"httpx.{err.__class__.__name__}: {err}") from err
telegram.error.NetworkError: httpx.LocalProtocolError: Invalid input ConnectionInputs.SEND_HEADERS in state ConnectionState.CLOSED
2023-05-02 23:04:21,265 ERROR Error while getting Updates: httpx.LocalProtocolError: Invalid input ConnectionInputs.SEND_HEADERS in state ConnectionState.CLOSED
2023-05-02 23:04:21,265 ERROR No error handlers are registered, logging exception.
Traceback (most recent call last):
  File "C:\Users\alexs\PythonProjects\AChtoZadano\.venv\Lib\site-packages\h2\connection.py", line 224, in process_input
    func, target_state = self._transitions[(self.state, input_)]
                         ~~~~~~~~~~~~~~~~~^^^^^^^^^^^^^^^^^^^^^^
KeyError: (<ConnectionState.CLOSED: 3>, <ConnectionInputs.SEND_HEADERS: 0>)

During handling of the above exception, another exception occurred:

Traceback (most recent call last):
  File "C:\Users\alexs\PythonProjects\AChtoZadano\.venv\Lib\site-packages\httpcore\_async\http2.py", line 106, in handle_async_request
    await self._send_request_headers(request=request, stream_id=stream_id)
  File "C:\Users\alexs\PythonProjects\AChtoZadano\.venv\Lib\site-packages\httpcore\_async\http2.py", line 203, in _send_request_headers
    self._h2_state.send_headers(stream_id, headers, end_stream=end_stream)
  File "C:\Users\alexs\PythonProjects\AChtoZadano\.venv\Lib\site-packages\h2\connection.py", line 766, in send_headers
    self.state_machine.process_input(ConnectionInputs.SEND_HEADERS)
  File "C:\Users\alexs\PythonProjects\AChtoZadano\.venv\Lib\site-packages\h2\connection.py", line 228, in process_input
    raise ProtocolError(
h2.exceptions.ProtocolError: Invalid input ConnectionInputs.SEND_HEADERS in state ConnectionState.CLOSED

During handling of the above exception, another exception occurred:

Traceback (most recent call last):
  File "C:\Users\alexs\PythonProjects\AChtoZadano\.venv\Lib\site-packages\httpx\_transports\default.py", line 60, in map_httpcore_exceptions
    yield
  File "C:\Users\alexs\PythonProjects\AChtoZadano\.venv\Lib\site-packages\httpx\_transports\default.py", line 353, in handle_async_request
    resp = await self._pool.handle_async_request(req)
           ^^^^^^^^^^^^^^^^^^^^^^^^^^^^^^^^^^^^^^^^^^
  File "C:\Users\alexs\PythonProjects\AChtoZadano\.venv\Lib\site-packages\httpcore\_async\connection_pool.py", line 253, in handle_async_request
    raise exc
  File "C:\Users\alexs\PythonProjects\AChtoZadano\.venv\Lib\site-packages\httpcore\_async\connection_pool.py", line 237, in handle_async_request
    response = await connection.handle_async_request(request)
               ^^^^^^^^^^^^^^^^^^^^^^^^^^^^^^^^^^^^^^^^^^^^^^
  File "C:\Users\alexs\PythonProjects\AChtoZadano\.venv\Lib\site-packages\httpcore\_async\connection.py", line 90, in handle_async_request
    return await self._connection.handle_async_request(request)
           ^^^^^^^^^^^^^^^^^^^^^^^^^^^^^^^^^^^^^^^^^^^^^^^^^^^^
  File "C:\Users\alexs\PythonProjects\AChtoZadano\.venv\Lib\site-packages\httpcore\_async\http2.py", line 142, in handle_async_request
    raise LocalProtocolError(exc)  # pragma: nocover
    ^^^^^^^^^^^^^^^^^^^^^^^^^^^^^
httpcore.LocalProtocolError: Invalid input ConnectionInputs.SEND_HEADERS in state ConnectionState.CLOSED

The above exception was the direct cause of the following exception:

Traceback (most recent call last):
  File "C:\Users\alexs\PythonProjects\AChtoZadano\.venv\Lib\site-packages\telegram\request\_httpxrequest.py", line 199, in do_request
    res = await self._client.request(
          ^^^^^^^^^^^^^^^^^^^^^^^^^^^
  File "C:\Users\alexs\PythonProjects\AChtoZadano\.venv\Lib\site-packages\httpx\_client.py", line 1533, in request
    return await self.send(request, auth=auth, follow_redirects=follow_redirects)
           ^^^^^^^^^^^^^^^^^^^^^^^^^^^^^^^^^^^^^^^^^^^^^^^^^^^^^^^^^^^^^^^^^^^^^^
  File "C:\Users\alexs\PythonProjects\AChtoZadano\.venv\Lib\site-packages\httpx\_client.py", line 1620, in send
    response = await self._send_handling_auth(
               ^^^^^^^^^^^^^^^^^^^^^^^^^^^^^^^
  File "C:\Users\alexs\PythonProjects\AChtoZadano\.venv\Lib\site-packages\httpx\_client.py", line 1648, in _send_handling_auth
    response = await self._send_handling_redirects(
               ^^^^^^^^^^^^^^^^^^^^^^^^^^^^^^^^^^^^
  File "C:\Users\alexs\PythonProjects\AChtoZadano\.venv\Lib\site-packages\httpx\_client.py", line 1685, in _send_handling_redirects
    response = await self._send_single_request(request)
               ^^^^^^^^^^^^^^^^^^^^^^^^^^^^^^^^^^^^^^^^
  File "C:\Users\alexs\PythonProjects\AChtoZadano\.venv\Lib\site-packages\httpx\_client.py", line 1722, in _send_single_request
    response = await transport.handle_async_request(request)
               ^^^^^^^^^^^^^^^^^^^^^^^^^^^^^^^^^^^^^^^^^^^^^
  File "C:\Users\alexs\PythonProjects\AChtoZadano\.venv\Lib\site-packages\httpx\_transports\default.py", line 352, in handle_async_request
    with map_httpcore_exceptions():
  File "C:\Program Files\Python311\Lib\contextlib.py", line 155, in __exit__
    self.gen.throw(typ, value, traceback)
  File "C:\Users\alexs\PythonProjects\AChtoZadano\.venv\Lib\site-packages\httpx\_transports\default.py", line 77, in map_httpcore_exceptions
    raise mapped_exc(message) from exc
httpx.LocalProtocolError: Invalid input ConnectionInputs.SEND_HEADERS in state ConnectionState.CLOSED

The above exception was the direct cause of the following exception:

Traceback (most recent call last):
  File "C:\Users\alexs\PythonProjects\AChtoZadano\.venv\Lib\site-packages\telegram\ext\_updater.py", line 607, in _network_loop_retry
    if not await action_cb():
           ^^^^^^^^^^^^^^^^^
  File "C:\Users\alexs\PythonProjects\AChtoZadano\.venv\Lib\site-packages\telegram\ext\_updater.py", line 335, in polling_action_cb
    raise exc
  File "C:\Users\alexs\PythonProjects\AChtoZadano\.venv\Lib\site-packages\telegram\ext\_updater.py", line 320, in polling_action_cb
    updates = await self.bot.get_updates(
              ^^^^^^^^^^^^^^^^^^^^^^^^^^^
  File "C:\Users\alexs\PythonProjects\AChtoZadano\.venv\Lib\site-packages\telegram\ext\_extbot.py", line 524, in get_updates
    updates = await super().get_updates(
              ^^^^^^^^^^^^^^^^^^^^^^^^^^
  File "C:\Users\alexs\PythonProjects\AChtoZadano\.venv\Lib\site-packages\telegram\_bot.py", line 331, in decorator
    result = await func(*args, **kwargs)  # skipcq: PYL-E1102
             ^^^^^^^^^^^^^^^^^^^^^^^^^^^
  File "C:\Users\alexs\PythonProjects\AChtoZadano\.venv\Lib\site-packages\telegram\_bot.py", line 3510, in get_updates
    await self._post(
  File "C:\Users\alexs\PythonProjects\AChtoZadano\.venv\Lib\site-packages\telegram\_bot.py", line 419, in _post
    return await self._do_post(
           ^^^^^^^^^^^^^^^^^^^^
  File "C:\Users\alexs\PythonProjects\AChtoZadano\.venv\Lib\site-packages\telegram\ext\_extbot.py", line 306, in _do_post
    return await super()._do_post(
           ^^^^^^^^^^^^^^^^^^^^^^^
  File "C:\Users\alexs\PythonProjects\AChtoZadano\.venv\Lib\site-packages\telegram\_bot.py", line 450, in _do_post
    return await request.post(
           ^^^^^^^^^^^^^^^^^^^
  File "C:\Users\alexs\PythonProjects\AChtoZadano\.venv\Lib\site-packages\telegram\request\_baserequest.py", line 165, in post
    result = await self._request_wrapper(
             ^^^^^^^^^^^^^^^^^^^^^^^^^^^^
  File "C:\Users\alexs\PythonProjects\AChtoZadano\.venv\Lib\site-packages\telegram\request\_baserequest.py", line 288, in _request_wrapper
    raise exc
  File "C:\Users\alexs\PythonProjects\AChtoZadano\.venv\Lib\site-packages\telegram\request\_baserequest.py", line 274, in _request_wrapper
    code, payload = await self.do_request(
                    ^^^^^^^^^^^^^^^^^^^^^^
  File "C:\Users\alexs\PythonProjects\AChtoZadano\.venv\Lib\site-packages\telegram\request\_httpxrequest.py", line 223, in do_request
    raise NetworkError(f"httpx.{err.__class__.__name__}: {err}") from err
telegram.error.NetworkError: httpx.LocalProtocolError: Invalid input ConnectionInputs.SEND_HEADERS in state ConnectionState.CLOSED
2023-05-02 23:04:24,664 ERROR Error while getting Updates: httpx.LocalProtocolError: Invalid input ConnectionInputs.SEND_HEADERS in state ConnectionState.CLOSED
2023-05-02 23:04:24,665 ERROR No error handlers are registered, logging exception.
Traceback (most recent call last):
  File "C:\Users\alexs\PythonProjects\AChtoZadano\.venv\Lib\site-packages\h2\connection.py", line 224, in process_input
    func, target_state = self._transitions[(self.state, input_)]
                         ~~~~~~~~~~~~~~~~~^^^^^^^^^^^^^^^^^^^^^^
KeyError: (<ConnectionState.CLOSED: 3>, <ConnectionInputs.SEND_HEADERS: 0>)

During handling of the above exception, another exception occurred:

Traceback (most recent call last):
  File "C:\Users\alexs\PythonProjects\AChtoZadano\.venv\Lib\site-packages\httpcore\_async\http2.py", line 106, in handle_async_request
    await self._send_request_headers(request=request, stream_id=stream_id)
  File "C:\Users\alexs\PythonProjects\AChtoZadano\.venv\Lib\site-packages\httpcore\_async\http2.py", line 203, in _send_request_headers
    self._h2_state.send_headers(stream_id, headers, end_stream=end_stream)
  File "C:\Users\alexs\PythonProjects\AChtoZadano\.venv\Lib\site-packages\h2\connection.py", line 766, in send_headers
    self.state_machine.process_input(ConnectionInputs.SEND_HEADERS)
  File "C:\Users\alexs\PythonProjects\AChtoZadano\.venv\Lib\site-packages\h2\connection.py", line 228, in process_input
    raise ProtocolError(
h2.exceptions.ProtocolError: Invalid input ConnectionInputs.SEND_HEADERS in state ConnectionState.CLOSED

During handling of the above exception, another exception occurred:

Traceback (most recent call last):
  File "C:\Users\alexs\PythonProjects\AChtoZadano\.venv\Lib\site-packages\httpx\_transports\default.py", line 60, in map_httpcore_exceptions
    yield
  File "C:\Users\alexs\PythonProjects\AChtoZadano\.venv\Lib\site-packages\httpx\_transports\default.py", line 353, in handle_async_request
    resp = await self._pool.handle_async_request(req)
           ^^^^^^^^^^^^^^^^^^^^^^^^^^^^^^^^^^^^^^^^^^
  File "C:\Users\alexs\PythonProjects\AChtoZadano\.venv\Lib\site-packages\httpcore\_async\connection_pool.py", line 253, in handle_async_request
    raise exc
  File "C:\Users\alexs\PythonProjects\AChtoZadano\.venv\Lib\site-packages\httpcore\_async\connection_pool.py", line 237, in handle_async_request
    response = await connection.handle_async_request(request)
               ^^^^^^^^^^^^^^^^^^^^^^^^^^^^^^^^^^^^^^^^^^^^^^
  File "C:\Users\alexs\PythonProjects\AChtoZadano\.venv\Lib\site-packages\httpcore\_async\connection.py", line 90, in handle_async_request
    return await self._connection.handle_async_request(request)
           ^^^^^^^^^^^^^^^^^^^^^^^^^^^^^^^^^^^^^^^^^^^^^^^^^^^^
  File "C:\Users\alexs\PythonProjects\AChtoZadano\.venv\Lib\site-packages\httpcore\_async\http2.py", line 142, in handle_async_request
    raise LocalProtocolError(exc)  # pragma: nocover
    ^^^^^^^^^^^^^^^^^^^^^^^^^^^^^
httpcore.LocalProtocolError: Invalid input ConnectionInputs.SEND_HEADERS in state ConnectionState.CLOSED

The above exception was the direct cause of the following exception:

Traceback (most recent call last):
  File "C:\Users\alexs\PythonProjects\AChtoZadano\.venv\Lib\site-packages\telegram\request\_httpxrequest.py", line 199, in do_request
    res = await self._client.request(
          ^^^^^^^^^^^^^^^^^^^^^^^^^^^
  File "C:\Users\alexs\PythonProjects\AChtoZadano\.venv\Lib\site-packages\httpx\_client.py", line 1533, in request
    return await self.send(request, auth=auth, follow_redirects=follow_redirects)
           ^^^^^^^^^^^^^^^^^^^^^^^^^^^^^^^^^^^^^^^^^^^^^^^^^^^^^^^^^^^^^^^^^^^^^^
  File "C:\Users\alexs\PythonProjects\AChtoZadano\.venv\Lib\site-packages\httpx\_client.py", line 1620, in send
    response = await self._send_handling_auth(
               ^^^^^^^^^^^^^^^^^^^^^^^^^^^^^^^
  File "C:\Users\alexs\PythonProjects\AChtoZadano\.venv\Lib\site-packages\httpx\_client.py", line 1648, in _send_handling_auth
    response = await self._send_handling_redirects(
               ^^^^^^^^^^^^^^^^^^^^^^^^^^^^^^^^^^^^
  File "C:\Users\alexs\PythonProjects\AChtoZadano\.venv\Lib\site-packages\httpx\_client.py", line 1685, in _send_handling_redirects
    response = await self._send_single_request(request)
               ^^^^^^^^^^^^^^^^^^^^^^^^^^^^^^^^^^^^^^^^
  File "C:\Users\alexs\PythonProjects\AChtoZadano\.venv\Lib\site-packages\httpx\_client.py", line 1722, in _send_single_request
    response = await transport.handle_async_request(request)
               ^^^^^^^^^^^^^^^^^^^^^^^^^^^^^^^^^^^^^^^^^^^^^
  File "C:\Users\alexs\PythonProjects\AChtoZadano\.venv\Lib\site-packages\httpx\_transports\default.py", line 352, in handle_async_request
    with map_httpcore_exceptions():
  File "C:\Program Files\Python311\Lib\contextlib.py", line 155, in __exit__
    self.gen.throw(typ, value, traceback)
  File "C:\Users\alexs\PythonProjects\AChtoZadano\.venv\Lib\site-packages\httpx\_transports\default.py", line 77, in map_httpcore_exceptions
    raise mapped_exc(message) from exc
httpx.LocalProtocolError: Invalid input ConnectionInputs.SEND_HEADERS in state ConnectionState.CLOSED

The above exception was the direct cause of the following exception:

Traceback (most recent call last):
  File "C:\Users\alexs\PythonProjects\AChtoZadano\.venv\Lib\site-packages\telegram\ext\_updater.py", line 607, in _network_loop_retry
    if not await action_cb():
           ^^^^^^^^^^^^^^^^^
  File "C:\Users\alexs\PythonProjects\AChtoZadano\.venv\Lib\site-packages\telegram\ext\_updater.py", line 335, in polling_action_cb
    raise exc
  File "C:\Users\alexs\PythonProjects\AChtoZadano\.venv\Lib\site-packages\telegram\ext\_updater.py", line 320, in polling_action_cb
    updates = await self.bot.get_updates(
              ^^^^^^^^^^^^^^^^^^^^^^^^^^^
  File "C:\Users\alexs\PythonProjects\AChtoZadano\.venv\Lib\site-packages\telegram\ext\_extbot.py", line 524, in get_updates
    updates = await super().get_updates(
              ^^^^^^^^^^^^^^^^^^^^^^^^^^
  File "C:\Users\alexs\PythonProjects\AChtoZadano\.venv\Lib\site-packages\telegram\_bot.py", line 331, in decorator
    result = await func(*args, **kwargs)  # skipcq: PYL-E1102
             ^^^^^^^^^^^^^^^^^^^^^^^^^^^
  File "C:\Users\alexs\PythonProjects\AChtoZadano\.venv\Lib\site-packages\telegram\_bot.py", line 3510, in get_updates
    await self._post(
  File "C:\Users\alexs\PythonProjects\AChtoZadano\.venv\Lib\site-packages\telegram\_bot.py", line 419, in _post
    return await self._do_post(
           ^^^^^^^^^^^^^^^^^^^^
  File "C:\Users\alexs\PythonProjects\AChtoZadano\.venv\Lib\site-packages\telegram\ext\_extbot.py", line 306, in _do_post
    return await super()._do_post(
           ^^^^^^^^^^^^^^^^^^^^^^^
  File "C:\Users\alexs\PythonProjects\AChtoZadano\.venv\Lib\site-packages\telegram\_bot.py", line 450, in _do_post
    return await request.post(
           ^^^^^^^^^^^^^^^^^^^
  File "C:\Users\alexs\PythonProjects\AChtoZadano\.venv\Lib\site-packages\telegram\request\_baserequest.py", line 165, in post
    result = await self._request_wrapper(
             ^^^^^^^^^^^^^^^^^^^^^^^^^^^^
  File "C:\Users\alexs\PythonProjects\AChtoZadano\.venv\Lib\site-packages\telegram\request\_baserequest.py", line 288, in _request_wrapper
    raise exc
  File "C:\Users\alexs\PythonProjects\AChtoZadano\.venv\Lib\site-packages\telegram\request\_baserequest.py", line 274, in _request_wrapper
    code, payload = await self.do_request(
                    ^^^^^^^^^^^^^^^^^^^^^^
  File "C:\Users\alexs\PythonProjects\AChtoZadano\.venv\Lib\site-packages\telegram\request\_httpxrequest.py", line 223, in do_request
    raise NetworkError(f"httpx.{err.__class__.__name__}: {err}") from err
telegram.error.NetworkError: httpx.LocalProtocolError: Invalid input ConnectionInputs.SEND_HEADERS in state ConnectionState.CLOSED
2023-05-02 23:19:28,395 INFO [31m[1mWARNING: This is a development server. Do not use it in a production deployment. Use a production WSGI server instead.[0m
 * Running on http://127.0.0.1:8080
2023-05-02 23:19:28,395 INFO [33mPress CTRL+C to quit[0m
2023-05-02 23:19:30,835 INFO Scheduler started
2023-05-02 23:19:30,836 INFO Application started
2023-05-02 23:19:45,775 INFO 127.0.0.1 - - [02/May/2023 23:19:45] "[32mGET /116 HTTP/1.1[0m" 302 -
2023-05-02 23:19:46,463 INFO 127.0.0.1 - - [02/May/2023 23:19:46] "GET /116/93 HTTP/1.1" 200 -
2023-05-02 23:19:47,020 INFO 127.0.0.1 - - [02/May/2023 23:19:47] "[36mGET /content/97c217b5812f49438591267ab949255a.png HTTP/1.1[0m" 304 -
2023-05-02 23:19:47,021 INFO 127.0.0.1 - - [02/May/2023 23:19:47] "[36mGET /content/8aceced8d7c841b2ad3316d2a7d10c7c.png HTTP/1.1[0m" 304 -
2023-05-02 23:19:47,062 INFO 127.0.0.1 - - [02/May/2023 23:19:47] "[36mGET /content/fc198f422cbb4d088e37fe9bf54bc849.png HTTP/1.1[0m" 304 -
2023-05-02 23:19:47,068 INFO 127.0.0.1 - - [02/May/2023 23:19:47] "[36mGET /content/logo.png HTTP/1.1[0m" 304 -
2023-05-02 23:19:47,075 INFO 127.0.0.1 - - [02/May/2023 23:19:47] "[36mGET /content/944de147944a49329c39b9b3cd722799.png HTTP/1.1[0m" 304 -
2023-05-02 23:19:47,481 INFO 127.0.0.1 - - [02/May/2023 23:19:47] "[33mGET /favicon.ico HTTP/1.1[0m" 404 -
